<?xml version="1.0"?>
<robot name="mall_robot" xmlns:xacro="http://ros.org/wiki/xacro">

    <!-- Define robot constants -->
    <xacro:property name="base_width" value="0.44"/>
    <xacro:property name="base_length" value="0.44"/>
    <xacro:property name="base_height" value="0.445"/>

    <xacro:property name="wheel_radius" value="0.1"/>
    <xacro:property name="wheel_width" value="0.03"/>
    <xacro:property name="wheel_ygap" value="0.062"/>
    <xacro:property name="wheel_zoff" value="0.1625"/>
    <xacro:property name="wheel_xoff" value="0.0"/>

    <xacro:property name="caster_xoff" value="0.21"/>
    <xacro:property name="caster_yoff" value="0.095"/>

    <xacro:property name="lidar_radius" value="0.038"/>
    <xacro:property name="lidar_height" value="0.041"/>

      <!-- Robot Base -->
    <link name="base_link">
        <visual>
        <geometry>
            <box size="${base_length} ${base_width} ${base_height}"/>
        </geometry>
        <material name="Grey">
            <color rgba="0.2 0.2 0.2 1.0"/>
        </material>
        </visual>
    </link>

      <!-- Robot Footprint -->
    <link name="base_footprint"/>

    <joint name="base_joint" type="fixed">
        <parent link="base_link"/>
        <child link="base_footprint"/>
        <origin xyz="0.0 0.0 ${-(wheel_radius+wheel_zoff)}" rpy="0 0 0"/>
    </joint>


      <!-- Wheels -->
    <xacro:macro name="wheel" params="prefix x_reflect y_reflect">
        <link name="${prefix}_link">
        <visual>
            <origin xyz="0 0 0" rpy="${pi/2} 0 0"/>
            <geometry>
                <cylinder radius="${wheel_radius}" length="${wheel_width}"/>
            </geometry>
            <material name="Black">
            <color rgba="0.0 0.0 0.0 1.0"/>
            </material>
        </visual>
        </link>

        <joint name="${prefix}_joint" type="continuous">
        <parent link="base_link"/>
        <child link="${prefix}_link"/>
        <origin xyz="${x_reflect*wheel_xoff} ${y_reflect*(base_width/2+wheel_ygap)} ${-wheel_zoff}" rpy="0 0 0"/>
        <axis xyz="0 1 0"/>
        </joint>
    </xacro:macro>

    <xacro:wheel prefix="drivewhl_l" x_reflect="-1" y_reflect="1" />
    <xacro:wheel prefix="drivewhl_r" x_reflect="-1" y_reflect="-1" />

      <!-- Caster Wheels -->
    <xacro:macro name="caster_wheel" params="prefix x_reflect y_reflect">
        <link name="${prefix}_link">
        <visual>
        <geometry>
            <sphere radius="${(wheel_radius+wheel_zoff-(base_height/2))}"/>
        </geometry>
        <material name="White">
            <color rgba="1.0 1.0 1.0 1.0"/>
        </material>
        </visual>
        </link>

        <joint name="${prefix}_joint" type="fixed">
            <parent link="base_link"/>
            <child link="${prefix}_link"/>
            <origin xyz="${x_reflect*caster_xoff} ${y_reflect*caster_yoff} ${-(base_height/2)}" rpy="0 0 0"/>
        </joint>
    </xacro:macro>

    <xacro:caster_wheel prefix="casterwhl_front_l" x_reflect="1" y_reflect="1" />
    <xacro:caster_wheel prefix="casterwhl_front_r" x_reflect="1" y_reflect="-1" />
    <xacro:caster_wheel prefix="casterwhl_back_l" x_reflect="-1" y_reflect="1" />
    <xacro:caster_wheel prefix="casterwhl_back_r" x_reflect="-1" y_reflect="-1" />

      <!-- Lidar -->
    <link name="lidar_link">
        <visual>
        <origin xyz="0 0 ${lidar_height/2}" rpy="0 0 0"/>
        <geometry>
            <cylinder radius="${lidar_radius}" length="${lidar_height}"/>
        </geometry>
        <material name="Black">
            <color rgba="0.0 0.0 0.0 1.0"/>
        </material>
        </visual>
    </link>

    <joint name="lidar_joint" type="fixed">
        <parent link="base_link"/>
        <child link="lidar_link"/>
        <origin xyz="0.0 0.0 0.22" rpy="0 0 0"/>
    </joint>

</robot>